Workbook

Sheet DETALLE
B1: ANÁLISIS DE PUNTOS DE FUNCIÓN — EcoWaste
B2: REQ | C2: Tipo | D2: Dificultad | E2: Puntos | G2: TOTAL | H2: Es_sub | J2: Tipo | K2: Baja | L2: Media | M2: Alta
A3: Registro de empresa | B3: Formulario de registro | C3: EI | D3: Baja | E3: =INDEX($K$3:$M$7,MATCH(C3,$J$3:$J$7,0),IF(UPPER(D3)="BAJA",1,IF(UPPER(D3)="MEDIA",2,3))) -> 3 | G3: =SUM(E4,E5,E6,E8,E16,E17,E19,E20,E22,E23,E24,E26,E38,E40,E41,E43,E44,E46,E47,E48,E50,E51,E52,E54,E55,E56) -> 124 | H3: 0 | J3: EI | K3: 3 | L3: 4 | M3: 6
B4: Validación de RUC y correo | C4: EQ | D4: Media | E4: =INDEX($K$3:$M$7,MATCH(C4,$J$3:$J$7,0),IF(UPPER(D4)="BAJA",1,IF(UPPER(D4)="MEDIA",2,3))) -> 4 | G4: puntos | H4: 1 | J4: EO | K4: 4 | L4: 5 | M4: 7
B5: Registrar empresa en BD | C5: ILF | D5: Baja | E5: =INDEX($K$3:$M$7,MATCH(C5,$J$3:$J$7,0),IF(UPPER(D5)="BAJA",1,IF(UPPER(D5)="MEDIA",2,3))) -> 7 | H5: 1 | J5: EQ | K5: 3 | L5: 4 | M5: 6
B6: Actualizar empresa | C6: ILF | D6: Baja | E6: =INDEX($K$3:$M$7,MATCH(C6,$J$3:$J$7,0),IF(UPPER(D6)="BAJA",1,IF(UPPER(D6)="MEDIA",2,3))) -> 7 | G6: Resumen | H6: 1 | J6: ILF | K6: 7 | L6: 10 | M6: 15
B7: Eliminar empresa | C7: ILF | D7: Baja | E7: =INDEX($K$3:$M$7,MATCH(C7,$J$3:$J$7,0),IF(UPPER(D7)="BAJA",1,IF(UPPER(D7)="MEDIA",2,3))) -> 7 | G7: Filas RF (azul): 10 | H7: 0 | J7: EIF | K7: 5 | L7: 7 | M7: 10
B8: Confirmación de registro | C8: EO | D8: Baja | E8: =INDEX($K$3:$M$7,MATCH(C8,$J$3:$J$7,0),IF(UPPER(D8)="BAJA",1,IF(UPPER(D8)="MEDIA",2,3))) -> 4 | G8: Sub-tareas: 26 | H8: 1
A9: EDICION DE EMPRESA | B9: Formulario de registro | C9: EI | D9: Baja | E9: =INDEX($K$3:$M$7,MATCH(C9,$J$3:$J$7,0),IF(UPPER(D9)="BAJA",1,IF(UPPER(D9)="MEDIA",2,3))) -> 3
B10: Validación de RUC y correo | C10: EQ | D10: Media | E10: =INDEX($K$3:$M$7,MATCH(C10,$J$3:$J$7,0),IF(UPPER(D10)="BAJA",1,IF(UPPER(D10)="MEDIA",2,3))) -> 4
B11: Registrar empresa en BD | C11: ILF | D11: Baja | E11: =INDEX($K$3:$M$7,MATCH(C11,$J$3:$J$7,0),IF(UPPER(D11)="BAJA",1,IF(UPPER(D11)="MEDIA",2,3))) -> 7
A16: Registro de persona natural | B16: Formulario de registro | C16: EI | D16: Baja | E16: =INDEX($K$3:$M$7,MATCH(C16,$J$3:$J$7,0),IF(UPPER(D16)="BAJA",1,IF(UPPER(D16)="MEDIA",2,3))) -> 3 | G16: El total suma solo sub-tareas | H16: 1
B17: Validación de DNI y correo | C17: EQ | D17: Media | E17: =INDEX($K$3:$M$7,MATCH(C17,$J$3:$J$7,0),IF(UPPER(D17)="BAJA",1,IF(UPPER(D17)="MEDIA",2,3))) -> 4 | H17: 1
B18: Registrar usuario | C18: ILF | D18: Baja | E18: =INDEX($K$3:$M$7,MATCH(C18,$J$3:$J$7,0),IF(UPPER(D18)="BAJA",1,IF(UPPER(D18)="MEDIA",2,3))) -> 7 | H18: 0
B19: Actualizar información | C19: ILF | D19: Baja | E19: =INDEX($K$3:$M$7,MATCH(C19,$J$3:$J$7,0),IF(UPPER(D19)="BAJA",1,IF(UPPER(D19)="MEDIA",2,3))) -> 7 | H19: 1
B20: Eliminar cuenta | C20: ILF | D20: Baja | E20: =INDEX($K$3:$M$7,MATCH(C20,$J$3:$J$7,0),IF(UPPER(D20)="BAJA",1,IF(UPPER(D20)="MEDIA",2,3))) -> 7 | H20: 1
B21: Confirmación de registro | C21: EO | D21: Baja | E21: =INDEX($K$3:$M$7,MATCH(C21,$J$3:$J$7,0),IF(UPPER(D21)="BAJA",1,IF(UPPER(D21)="MEDIA",2,3))) -> 4 | H21: 0
A22: Perfil de usuario | B22: Visualizar perfil | C22: EQ | D22: Baja | E22: =INDEX($K$3:$M$7,MATCH(C22,$J$3:$J$7,0),IF(UPPER(D22)="BAJA",1,IF(UPPER(D22)="MEDIA",2,3))) -> 3 | H22: 1
B23: Editar perfil | C23: EI | D23: Baja | E23: =INDEX($K$3:$M$7,MATCH(C23,$J$3:$J$7,0),IF(UPPER(D23)="BAJA",1,IF(UPPER(D23)="MEDIA",2,3))) -> 3 | H23: 1
B24: Actualizar perfil | C24: ILF | D24: Baja | E24: =INDEX($K$3:$M$7,MATCH(C24,$J$3:$J$7,0),IF(UPPER(D24)="BAJA",1,IF(UPPER(D24)="MEDIA",2,3))) -> 7 | H24: 1
B25: Cambiar contraseña | C25: EI | D25: Media | E25: =INDEX($K$3:$M$7,MATCH(C25,$J$3:$J$7,0),IF(UPPER(D25)="BAJA",1,IF(UPPER(D25)="MEDIA",2,3))) -> 4 | H25: 0
B26: Actualizar contraseña | C26: ILF | D26: Media | E26: =INDEX($K$3:$M$7,MATCH(C26,$J$3:$J$7,0),IF(UPPER(D26)="BAJA",1,IF(UPPER(D26)="MEDIA",2,3))) -> 10 | H26: 1
A27: Perfil de usuario
B28: FORMULARIO DE CONSULTA
B29: Obtener Datos de Usuario+
A38: Inicio de sesión | B38: Formulario Login | C38: EI | D38: Baja | E38: =INDEX($K$3:$M$7,MATCH(C38,$J$3:$J$7,0),IF(UPPER(D38)="BAJA",1,IF(UPPER(D38)="MEDIA",2,3))) -> 3 | H38: 1
B39: Validar credenciales | C39: EQ | D39: Media | E39: =INDEX($K$3:$M$7,MATCH(C39,$J$3:$J$7,0),IF(UPPER(D39)="BAJA",1,IF(UPPER(D39)="MEDIA",2,3))) -> 4 | H39: 0
B40: Generar sesión | C40: EO | D40: Media | E40: =INDEX($K$3:$M$7,MATCH(C40,$J$3:$J$7,0),IF(UPPER(D40)="BAJA",1,IF(UPPER(D40)="MEDIA",2,3))) -> 5 | H40: 1
B41: Consultar rol | C41: EQ | D41: Baja | E41: =INDEX($K$3:$M$7,MATCH(C41,$J$3:$J$7,0),IF(UPPER(D41)="BAJA",1,IF(UPPER(D41)="MEDIA",2,3))) -> 3 | H41: 1
A42: Hacer publicación | B42: Formulario publicación | C42: EI | D42: Baja | E42: =INDEX($K$3:$M$7,MATCH(C42,$J$3:$J$7,0),IF(UPPER(D42)="BAJA",1,IF(UPPER(D42)="MEDIA",2,3))) -> 3 | H42: 0
B43: Registrar publicación | C43: ILF | D43: Baja | E43: =INDEX($K$3:$M$7,MATCH(C43,$J$3:$J$7,0),IF(UPPER(D43)="BAJA",1,IF(UPPER(D43)="MEDIA",2,3))) -> 7 | H43: 1
B44: Editar publicación | C44: ILF | D44: Baja | E44: =INDEX($K$3:$M$7,MATCH(C44,$J$3:$J$7,0),IF(UPPER(D44)="BAJA",1,IF(UPPER(D44)="MEDIA",2,3))) -> 7 | H44: 1
B45: Eliminar publicación | C45: ILF | D45: Baja | E45: =INDEX($K$3:$M$7,MATCH(C45,$J$3:$J$7,0),IF(UPPER(D45)="BAJA",1,IF(UPPER(D45)="MEDIA",2,3))) -> 7 | H45: 0
B46: Adjuntar imágenes | C46: EI | D46: Media | E46: =INDEX($K$3:$M$7,MATCH(C46,$J$3:$J$7,0),IF(UPPER(D46)="BAJA",1,IF(UPPER(D46)="MEDIA",2,3))) -> 4 | H46: 1
B47: Mostrar publicación creada | C47: EO | D47: Baja | E47: =INDEX($K$3:$M$7,MATCH(C47,$J$3:$J$7,0),IF(UPPER(D47)="BAJA",1,IF(UPPER(D47)="MEDIA",2,3))) -> 4 | H47: 1
A48: Búsqueda de materiales | B48: Buscar por nombre | C48: EQ | D48: Baja | E48: =INDEX($K$3:$M$7,MATCH(C48,$J$3:$J$7,0),IF(UPPER(D48)="BAJA",1,IF(UPPER(D48)="MEDIA",2,3))) -> 3 | H48: 1
B49: Buscar por categoría | C49: EQ | D49: Baja | E49: =INDEX($K$3:$M$7,MATCH(C49,$J$3:$J$7,0),IF(UPPER(D49)="BAJA",1,IF(UPPER(D49)="MEDIA",2,3))) -> 3 | H49: 0
B50: Buscar por ubicación | C50: EQ | D50: Media | E50: =INDEX($K$3:$M$7,MATCH(C50,$J$3:$J$7,0),IF(UPPER(D50)="BAJA",1,IF(UPPER(D50)="MEDIA",2,3))) -> 4 | H50: 1
B51: Mostrar resultados | C51: EO | D51: Media | E51: =INDEX($K$3:$M$7,MATCH(C51,$J$3:$J$7,0),IF(UPPER(D51)="BAJA",1,IF(UPPER(D51)="MEDIA",2,3))) -> 5 | H51: 1
A52: Filtrado y ordenamiento | B52: Filtrar por categoría | C52: EQ | D52: Baja | E52: =INDEX($K$3:$M$7,MATCH(C52,$J$3:$J$7,0),IF(UPPER(D52)="BAJA",1,IF(UPPER(D52)="MEDIA",2,3))) -> 3 | H52: 1
...

Sheet RESUMEN
A1: Resumen por tipo de función
A3: Tipo | B3: Cantidad | C3: Puntos | D3: % del total
A4: EI | B4: =COUNTIFS(DETALLE!$C$3:$C$56,A4,DETALLE!$H$3:$H$56,1) -> 5 | C4: =SUMIFS(DETALLE!$E$3:$E$56,DETALLE!$C$3:$C$56,A4,DETALLE!$H$3:$H$56,1) -> 16 | D4: =IFERROR(C4/$C$9,0) -> 0.12903226
A5: EO | B5: =COUNTIFS(DETALLE!$C$3:$C$56,A5,DETALLE!$H$3:$H$56,1) -> 5 | C5: =SUMIFS(DETALLE!$E$3:$E$56,DETALLE!$C$3:$C$56,A5,DETALLE!$H$3:$H$56,1) -> 22 | D5: =IFERROR(C5/$C$9,0) -> 0.17741935
A6: EQ | B6: =COUNTIFS(DETALLE!$C$3:$C$56,A6,DETALLE!$H$3:$H$56,1) -> 8 | C6: =SUMIFS(DETALLE!$E$3:$E$56,DETALLE!$C$3:$C$56,A6,DETALLE!$H$3:$H$56,1) -> 27 | D6: =IFERROR(C6/$C$9,0) -> 0.21774194
A7: ILF | B7: =COUNTIFS(DETALLE!$C$3:$C$56,A7,DETALLE!$H$3:$H$56,1) -> 8 | C7: =SUMIFS(DETALLE!$E$3:$E$56,DETALLE!$C$3:$C$56,A7,DETALLE!$H$3:$H$56,1) -> 59 | D7: =IFERROR(C7/$C$9,0) -> 0.47580645
A8: EIF | B8: =COUNTIFS(DETALLE!$C$3:$C$56,A8,DETALLE!$H$3:$H$56,1) -> 0 | C8: =SUMIFS(DETALLE!$E$3:$E$56,DETALLE!$C$3:$C$56,A8,DETALLE!$H$3:$H$56,1) -> 0 | D8: =IFERROR(C8/$C$9,0) -> 0
A9: TOTAL | B9: =SUM(B4:B8) -> 26 | C9: =SUM(C4:C8) -> 124 | D9: 100%

Sheet Hoja1
B3: Requerimiento Funcional | C3: Derivación | D3: Tipo | E3: Justificación | F3: Complejidad (Sugerida)
B4: Registro de empresa | C4: Formulario de registro | D4: EI | E4: Captura datos de la empresa | F4: Baja
C5: Validación de RUC y correo | D5: EQ | E5: Consulta para verificar existencia | F5: Media
C6: Registrar empresa en BD | D6: ILF | E6: INSERT de empresa | F6: Baja
C7: Actualizar empresa | D7: ILF | E7: UPDATE de empresa | F7: Baja
C8: Eliminar empresa | D8: ILF | E8: DELETE lógico | F8: Baja
C9: Confirmación de registro | D9: EO | E9: Mensaje de confirmación | F9: Baja
B10: Registro de persona natural | C10: Formulario de registro | D10: EI | E10: Captura información personal | F10: Baja
C11: Validación de DNI y correo | D11: EQ | E11: Consulta de duplicidad | F11: Media
C12: Registrar usuario | D12: ILF | E12: INSERT | F12: Baja
C13: Actualizar información | D13: ILF | E13: UPDATE | F13: Baja
C14: Eliminar cuenta | D14: ILF | E14: DELETE lógico | F14: Baja
C15: Confirmación de registro | D15: EO | E15: Mensaje al usuario | F15: Baja
B16: Perfil de usuario | C16: Visualizar perfil | D16: EQ | E16: Consulta de datos | F16: Baja
C17: Editar perfil | D17: EI | E17: Formulario de edición | F17: Baja
C18: Actualizar perfil | D18: ILF | E18: UPDATE | F18: Baja
C19: Cambiar contraseña | D19: EI | E19: Entrada de nueva contraseña | F19: Media
C20: Actualizar contraseña | D20: ILF | E20: UPDATE | F20: Media
B21: Inicio de sesión | C21: Formulario Login | D21: EI | E21: Captura credenciales | F21: Baja
C22: Validar credenciales | D22: EQ | E22: Consulta de usuario | F22: Media
C23: Generar sesión | D23: EO | E23: Devuelve token o sesión | F23: Media
C24: Consultar rol | D24: EQ | E24: Consulta permisos | F24: Baja
B25: Hacer publicación | C25: Formulario publicación | D25: EI | E25: Registro de material | F25: Baja
C26: Registrar publicación | D26: ILF | E26: INSERT | F26: Baja
C27: Editar publicación | D27: ILF | E27: UPDATE | F27: Baja
C28: Eliminar publicación | D28: ILF | E28: DELETE lógico | F28: Baja
C29: Adjuntar imágenes | D29: EI | E29: Carga de archivos | F29: Media
C30: Mostrar publicación creada | D30: EO | E30: Confirmación | F30: Baja
B31: Búsqueda de materiales | C31: Buscar por nombre | D31: EQ | E31: Consulta BD | F31: Baja
C32: Buscar por categoría | D32: EQ | E32: Consulta | F32: Baja
C33: Buscar por ubicación | D33: EQ | E33: Consulta | F33: Media
C34: Mostrar resultados | D34: EO | E34: Lista de resultados | F34: Media
B35: Filtrado y ordenamiento | C35: Filtrar por categoría | D35: EQ | E35: Consulta | F35: Baja
C36: Filtrar por precio | D36: EQ | E36: Consulta | F36: Baja
C37: Ordenar resultados | D37: EQ | E37: Consulta ordenada | F37: Baja
C38: Mostrar lista filtrada | D38: EO | E38: Resultado | F38: Baja
B39: Envío de mensajes | C39: Formulario mensaje | D39: EI | E39: Captura mensaje | F39: Baja
C40: Registrar mensaje | D40: ILF | E40: INSERT | F40: Baja
C41: Consultar conversación | D41: EQ | E41: Consulta historial | F41: Media
C42: Mostrar conversación | D42: EO | E42: Presentación | F42: Baja
...
